Traceback (most recent call last):
  File "/config/workspace/turing-commons/.venv/lib/python3.6/site-packages/jupyter_cache/executors/utils.py", line 56, in single_nb_execution
    record_timing=False,
  File "/config/workspace/turing-commons/.venv/lib/python3.6/site-packages/nbclient/client.py", line 1093, in execute
    return NotebookClient(nb=nb, resources=resources, km=km, **kwargs).execute()
  File "/config/workspace/turing-commons/.venv/lib/python3.6/site-packages/nbclient/util.py", line 84, in wrapped
    return just_run(coro(*args, **kwargs))
  File "/config/workspace/turing-commons/.venv/lib/python3.6/site-packages/nbclient/util.py", line 62, in just_run
    return loop.run_until_complete(coro)
  File "/usr/lib/python3.6/asyncio/base_events.py", line 484, in run_until_complete
    return future.result()
  File "/config/workspace/turing-commons/.venv/lib/python3.6/site-packages/nbclient/client.py", line 560, in async_execute
    cell, index, execution_count=self.code_cells_executed + 1
  File "/config/workspace/turing-commons/.venv/lib/python3.6/site-packages/nbclient/client.py", line 854, in async_execute_cell
    self._check_raise_for_error(cell, exec_reply)
  File "/config/workspace/turing-commons/.venv/lib/python3.6/site-packages/nbclient/client.py", line 756, in _check_raise_for_error
    raise CellExecutionError.from_cell_and_msg(cell, exec_reply_content)
nbclient.exceptions.CellExecutionError: An error occurred while executing the following cell:
------------------
import numpy as np
import matplotlib.pyplot as plt

# setting values for x
mu1, mu2, sigma = 50,80, 15
x1 = mu1+sigma*np.random.randn(10000)
x2 = mu2+sigma*np.random.randn(10000)
fig, axes = plt.subplots(1,2,figsize=(12,5))

# distibution t=1
n, bins, patches = axes[0].hist(x1, 50, density=True, facecolor='g', alpha=0.75)
axes[0].set_title('Distribution T=1')
axes[0].set_xlim(0, 100)
axes[0].set_ylim(0, 0.03)
axes[0].grid(True)

# distribution t=2
n, bins, patches = axes[1].hist(x2, 50, density=True, facecolor='b', alpha=0.75)
axes[1].set_title('Distribution T=2')
axes[1].set_xlim(0, 100)
axes[1].set_ylim(0, 0.03)
axes[1].grid(True)
plt.show()
------------------

[0;31m---------------------------------------------------------------------------[0m
[0;31mModuleNotFoundError[0m                       Traceback (most recent call last)
[0;32m<ipython-input-1-cf2801c31536>[0m in [0;36m<module>[0;34m[0m
[0;32m----> 1[0;31m [0;32mimport[0m [0mnumpy[0m [0;32mas[0m [0mnp[0m[0;34m[0m[0;34m[0m[0m
[0m[1;32m      2[0m [0;32mimport[0m [0mmatplotlib[0m[0;34m.[0m[0mpyplot[0m [0;32mas[0m [0mplt[0m[0;34m[0m[0;34m[0m[0m
[1;32m      3[0m [0;34m[0m[0m
[1;32m      4[0m [0;31m# setting values for x[0m[0;34m[0m[0;34m[0m[0;34m[0m[0m
[1;32m      5[0m [0mmu1[0m[0;34m,[0m [0mmu2[0m[0;34m,[0m [0msigma[0m [0;34m=[0m [0;36m50[0m[0;34m,[0m[0;36m80[0m[0;34m,[0m [0;36m15[0m[0;34m[0m[0;34m[0m[0m

[0;31mModuleNotFoundError[0m: No module named 'numpy'
ModuleNotFoundError: No module named 'numpy'

